30
1
logRMM6hr_6maps_dailyinput_mem1d_lead30
Traceback (most recent call last):
  File "/global/homes/l/linyaoly/.local/perlmutter/pytorch1.11.0/lib/python3.9/site-packages/xarray/backends/file_manager.py", line 201, in _acquire_with_cache_info
    file = self._cache[self._key]
  File "/global/homes/l/linyaoly/.local/perlmutter/pytorch1.11.0/lib/python3.9/site-packages/xarray/backends/lru_cache.py", line 55, in __getitem__
    value = self._cache[key]
KeyError: [<class 'netCDF4._netCDF4.Dataset'>, ('/global/homes/l/linyaoly/ERA5/reanalysis/u200_2deg2017.nc',), 'r', (('clobber', True), ('diskless', False), ('format', 'NETCDF4'), ('persist', False))]

During handling of the above exception, another exception occurred:

Traceback (most recent call last):
  File "/global/u1/l/linyaoly/ERA5/script/Stability-Explanability/6maps_35yrtraining_RMMERA5_6hr/Unet4MJO.py", line 95, in <module>
    ds = xr.open_dataset(Fn1[0])
  File "/global/homes/l/linyaoly/.local/perlmutter/pytorch1.11.0/lib/python3.9/site-packages/xarray/backends/api.py", line 531, in open_dataset
    backend_ds = backend.open_dataset(
  File "/global/homes/l/linyaoly/.local/perlmutter/pytorch1.11.0/lib/python3.9/site-packages/xarray/backends/netCDF4_.py", line 555, in open_dataset
    store = NetCDF4DataStore.open(
  File "/global/homes/l/linyaoly/.local/perlmutter/pytorch1.11.0/lib/python3.9/site-packages/xarray/backends/netCDF4_.py", line 384, in open
    return cls(manager, group=group, mode=mode, lock=lock, autoclose=autoclose)
  File "/global/homes/l/linyaoly/.local/perlmutter/pytorch1.11.0/lib/python3.9/site-packages/xarray/backends/netCDF4_.py", line 332, in __init__
    self.format = self.ds.data_model
  File "/global/homes/l/linyaoly/.local/perlmutter/pytorch1.11.0/lib/python3.9/site-packages/xarray/backends/netCDF4_.py", line 393, in ds
    return self._acquire()
  File "/global/homes/l/linyaoly/.local/perlmutter/pytorch1.11.0/lib/python3.9/site-packages/xarray/backends/netCDF4_.py", line 387, in _acquire
    with self._manager.acquire_context(needs_lock) as root:
  File "/global/common/software/nersc/pm-2021q4/sw/pytorch/1.11.0/lib/python3.9/contextlib.py", line 119, in __enter__
    return next(self.gen)
  File "/global/homes/l/linyaoly/.local/perlmutter/pytorch1.11.0/lib/python3.9/site-packages/xarray/backends/file_manager.py", line 189, in acquire_context
    file, cached = self._acquire_with_cache_info(needs_lock)
  File "/global/homes/l/linyaoly/.local/perlmutter/pytorch1.11.0/lib/python3.9/site-packages/xarray/backends/file_manager.py", line 207, in _acquire_with_cache_info
    file = self._opener(*self._args, **kwargs)
  File "src/netCDF4/_netCDF4.pyx", line 2307, in netCDF4._netCDF4.Dataset.__init__
  File "src/netCDF4/_netCDF4.pyx", line 1925, in netCDF4._netCDF4._ensure_nc_success
FileNotFoundError: [Errno 2] No such file or directory: b'/global/homes/l/linyaoly/ERA5/reanalysis/u200_2deg2017.nc'
srun: error: nid001665: task 0: Exited with exit code 1
srun: launch/slurm: _step_signal: Terminating StepId=3334705.0
