/opt/cray/pe/lmod/lmod/init/csh: line 2: setenv: command not found
/opt/cray/pe/lmod/lmod/init/csh: line 3: setenv: command not found
/opt/cray/pe/lmod/lmod/init/csh: line 4: setenv: command not found
/opt/cray/pe/lmod/lmod/init/csh: line 5: setenv: command not found
/opt/cray/pe/lmod/lmod/init/csh: line 6: setenv: command not found
/opt/cray/pe/lmod/lmod/init/csh: line 7: setenv: command not found
/opt/cray/pe/lmod/lmod/init/csh: line 8: setenv: command not found
/opt/cray/pe/lmod/lmod/init/csh: line 63: syntax error: unexpected end of file

The following have been reloaded with a version change:
  1) cudatoolkit/11.7 => cudatoolkit/11.5

Traceback (most recent call last):
  File "/global/homes/l/linyaoly/.local/perlmutter/pytorch1.11.0/lib/python3.9/site-packages/xarray/backends/file_manager.py", line 201, in _acquire_with_cache_info
    file = self._cache[self._key]
  File "/global/homes/l/linyaoly/.local/perlmutter/pytorch1.11.0/lib/python3.9/site-packages/xarray/backends/lru_cache.py", line 55, in __getitem__
    value = self._cache[key]
KeyError: [<class 'netCDF4._netCDF4.Dataset'>, ('/pscratch/sd/l/linyaoly/ERA5/reanalysis/ERA5.sstGfltGmask0.day.1979to2022.nc',), 'r', (('clobber', True), ('diskless', False), ('format', 'NETCDF4'), ('persist', False))]

During handling of the above exception, another exception occurred:

Traceback (most recent call last):
  File "/global/u1/l/linyaoly/ERA5/script/Unet4MJO/19maps_MCDO_36yrtraining_ROMIERA5_filtered_trop/ReloadUnet4MJO_mcdp.py", line 170, in <module>
    psi_test_input_Tr_torch, psi_test_label_Tr_torch, psi_test_label_Tr  = load_test_data(Fn,vn,Fnmjo,leadmjo,mem_list,testyn,lat_lim)
  File "/global/u1/l/linyaoly/ERA5/script/Unet4MJO/19maps_MCDO_36yrtraining_ROMIERA5_filtered_trop/Reloaddata_loader_loop.py", line 30, in load_test_data
    FF0 = xr.open_dataset(Fn[ivn])  
  File "/global/homes/l/linyaoly/.local/perlmutter/pytorch1.11.0/lib/python3.9/site-packages/xarray/backends/api.py", line 531, in open_dataset
    backend_ds = backend.open_dataset(
  File "/global/homes/l/linyaoly/.local/perlmutter/pytorch1.11.0/lib/python3.9/site-packages/xarray/backends/netCDF4_.py", line 555, in open_dataset
    store = NetCDF4DataStore.open(
  File "/global/homes/l/linyaoly/.local/perlmutter/pytorch1.11.0/lib/python3.9/site-packages/xarray/backends/netCDF4_.py", line 384, in open
    return cls(manager, group=group, mode=mode, lock=lock, autoclose=autoclose)
  File "/global/homes/l/linyaoly/.local/perlmutter/pytorch1.11.0/lib/python3.9/site-packages/xarray/backends/netCDF4_.py", line 332, in __init__
    self.format = self.ds.data_model
  File "/global/homes/l/linyaoly/.local/perlmutter/pytorch1.11.0/lib/python3.9/site-packages/xarray/backends/netCDF4_.py", line 393, in ds
    return self._acquire()
  File "/global/homes/l/linyaoly/.local/perlmutter/pytorch1.11.0/lib/python3.9/site-packages/xarray/backends/netCDF4_.py", line 387, in _acquire
    with self._manager.acquire_context(needs_lock) as root:
  File "/global/common/software/nersc/pm-2021q4/sw/pytorch/1.11.0/lib/python3.9/contextlib.py", line 119, in __enter__
    return next(self.gen)
  File "/global/homes/l/linyaoly/.local/perlmutter/pytorch1.11.0/lib/python3.9/site-packages/xarray/backends/file_manager.py", line 189, in acquire_context
    file, cached = self._acquire_with_cache_info(needs_lock)
  File "/global/homes/l/linyaoly/.local/perlmutter/pytorch1.11.0/lib/python3.9/site-packages/xarray/backends/file_manager.py", line 207, in _acquire_with_cache_info
    file = self._opener(*self._args, **kwargs)
  File "src/netCDF4/_netCDF4.pyx", line 2307, in netCDF4._netCDF4.Dataset.__init__
  File "src/netCDF4/_netCDF4.pyx", line 1925, in netCDF4._netCDF4._ensure_nc_success
FileNotFoundError: [Errno 2] No such file or directory: b'/pscratch/sd/l/linyaoly/ERA5/reanalysis/ERA5.sstGfltGmask0.day.1979to2022.nc'
srun: error: nid001425: task 0: Exited with exit code 1
srun: Terminating StepId=8682534.0
